<?xml version="1.0" ?>
<!-- =================================================================================== -->
<!-- |    This document was autogenerated by xacro from /home/reachy/reachy_ws/install/reachy_description/share/reachy_description/urdf/reachy.urdf.xacro | -->
<!-- |    EDITING THIS FILE BY HAND IS NOT RECOMMENDED                                 | -->
<!-- =================================================================================== -->
<robot name="reachy2">
  <!-- convergence angle (rad) of the cameras. 0=parallel-->
  <!-- URDF definition is so stupid we have to do that... -->
  <!-- <material name="gripperblack"> -->
  <!--     <color rgba="0.4 0.4 0.4 1"/> -->
  <!-- </material> -->
  <!-- <material name="gripperwhite"> -->
  <!--     <color rgba="0.9 0.9 0.9 1"/> -->
  <!-- </material> -->
  <!-- <material name="reachy_yellow"> -->
  <!--     <color rgba="0.8 0.8 0.0 1"/> -->
  <!-- </material> -->
  <!-- <material name="reachy_grey"> -->
  <!--     <color rgba="0.8 0.8 0.8 1"/> -->
  <!-- </material> -->
  <!-- <material name="reachy_metal"> -->
  <!--     <color rgba="0.85 0.85 0.85 1.0"/> -->
  <!-- </material> -->
  <!-- <material name="torsoblack"> -->
  <!--     <color rgba="0.5 0.5 0.5 1.0"/> -->
  <!-- </material> -->
  <!-- <material name="eyewhite"> -->
  <!--     <color rgba="1.0 1.0 1.0 1.0"/> -->
  <!-- </material> -->
  <!-- <material name="orbita2dmetal"> -->
  <!--     <color rgba="0.85 0.85 0.85 1.0"/> -->
  <!-- </material> -->
  <!-- <material name="orbita2dgrey"> -->
  <!--     <color rgba="0.8 0.8 0.8 1.0"/> -->
  <!-- </material> -->
  <!-- <material name="orbita3d_yellow"> -->
  <!--     <color rgba="0.8 0.8 0.0 1"/> -->
  <!-- </material> -->
  <!-- <material name="orbita3d_grey"> -->
  <!--     <color rgba="0.8 0.8 0.8 1"/> -->
  <!-- </material> -->
  <material name="camblack">
    <color rgba="0.2 0.2 0.2 1"/>
  </material>
  <material name="neckwhite">
    <color rgba="0.9 0.9 0.9 1"/>
  </material>
  <!-- URDF definition is so stupid we have to do that... -->
  <!-- <material name="gripperblack"> -->
  <!--     <color rgba="0.4 0.4 0.4 1"/> -->
  <!-- </material> -->
  <!-- <material name="gripperwhite"> -->
  <!--     <color rgba="0.9 0.9 0.9 1"/> -->
  <!-- </material> -->
  <!-- <material name="reachy_yellow"> -->
  <!--     <color rgba="0.8 0.8 0.0 1"/> -->
  <!-- </material> -->
  <!-- <material name="reachy_grey"> -->
  <!--     <color rgba="0.8 0.8 0.8 1"/> -->
  <!-- </material> -->
  <!-- <material name="reachy_metal"> -->
  <!--     <color rgba="0.85 0.85 0.85 1.0"/> -->
  <!-- </material> -->
  <!-- <material name="torsoblack"> -->
  <!--     <color rgba="0.5 0.5 0.5 1.0"/> -->
  <!-- </material> -->
  <!-- <material name="eyewhite"> -->
  <!--     <color rgba="1.0 1.0 1.0 1.0"/> -->
  <!-- </material> -->
  <!-- <material name="orbita2dmetal"> -->
  <!--     <color rgba="0.85 0.85 0.85 1.0"/> -->
  <!-- </material> -->
  <!-- <material name="orbita2dgrey"> -->
  <!--     <color rgba="0.8 0.8 0.8 1.0"/> -->
  <!-- </material> -->
  <!-- <material name="orbita3d_yellow"> -->
  <!--     <color rgba="0.8 0.8 0.0 1"/> -->
  <!-- </material> -->
  <!-- <material name="orbita3d_grey"> -->
  <!--     <color rgba="0.8 0.8 0.8 1"/> -->
  <!-- </material> -->
  <!-- URDF definition is so stupid we have to do that... -->
  <!-- <material name="gripperblack"> -->
  <!--     <color rgba="0.4 0.4 0.4 1"/> -->
  <!-- </material> -->
  <!-- <material name="gripperwhite"> -->
  <!--     <color rgba="0.9 0.9 0.9 1"/> -->
  <!-- </material> -->
  <!-- <material name="reachy_yellow"> -->
  <!--     <color rgba="0.8 0.8 0.0 1"/> -->
  <!-- </material> -->
  <!-- <material name="reachy_grey"> -->
  <!--     <color rgba="0.8 0.8 0.8 1"/> -->
  <!-- </material> -->
  <!-- <material name="reachy_metal"> -->
  <!--     <color rgba="0.85 0.85 0.85 1.0"/> -->
  <!-- </material> -->
  <!-- <material name="torsoblack"> -->
  <!--     <color rgba="0.5 0.5 0.5 1.0"/> -->
  <!-- </material> -->
  <!-- <material name="eyewhite"> -->
  <!--     <color rgba="1.0 1.0 1.0 1.0"/> -->
  <!-- </material> -->
  <!-- <material name="orbita2dmetal"> -->
  <!--     <color rgba="0.85 0.85 0.85 1.0"/> -->
  <!-- </material> -->
  <!-- <material name="orbita2dgrey"> -->
  <!--     <color rgba="0.8 0.8 0.8 1.0"/> -->
  <!-- </material> -->
  <!-- <material name="orbita3d_yellow"> -->
  <!--     <color rgba="0.8 0.8 0.0 1"/> -->
  <!-- </material> -->
  <!-- <material name="orbita3d_grey"> -->
  <!--     <color rgba="0.8 0.8 0.8 1"/> -->
  <!-- </material> -->
  <!-- <material name="orbita2dmetal"> -->
  <!--     <color rgba="0.85 0.85 0.85 1.0"/> -->
  <!-- </material> -->
  <!-- <material name="orbita2dgrey"> -->
  <!--     <color rgba="0.8 0.8 0.8 1.0"/> -->
  <!-- </material> -->
  <!-- config  -->
  <!-- MODEL PARAMETERS -->
  <!-- <material name="torsoblack"> -->
  <!--     <color rgba="0.5 0.5 0.5 1.0"/> -->
  <!-- </material> -->
  <link name="world"/>
  <joint name="world_joint" type="fixed">
    <origin rpy="0 0 0" xyz="0 0 1.0"/>
    <parent link="world"/>
    <child link="torso"/>
  </joint>
  <!-- TORSO -->
  <link name="torso">
    <collision>
      <origin rpy="0 0.0 0" xyz="-0.05 0 -0.05"/>
      <geometry>
        <box size="0.1 0.2 0.22"/>
      </geometry>
      <!-- <origin xyz="0 0 -0.5" rpy="0 0 0"/> -->
      <!-- <geometry> -->
      <!--   <cylinder length="1" radius="0.03"/> -->
      <!-- </geometry> -->
    </collision>
    <collision>
      <origin rpy="0 0 0" xyz="-0.15 0 -0.5"/>
      <geometry>
        <cylinder length="1" radius="0.03"/>
      </geometry>
    </collision>
    <visual>
      <origin rpy="0 0.0 0" xyz="-0.05 0 -0.05"/>
      <geometry>
        <box size="0.1 0.2 0.22"/>
      </geometry>
      <material name="torsoblack">
        <color rgba="0.5 0.5 0.5 1.0"/>
      </material>
    </visual>
    <visual>
      <origin rpy="0 0 0" xyz="-0.15 0 -0.5"/>
      <geometry>
        <cylinder length="1" radius="0.03"/>
      </geometry>
      <material name="torsoblack">
        <color rgba="0.5 0.5 0.5 1.0"/>
      </material>
    </visual>
    <inertial>
      <mass value="10"/>
      <origin rpy="0 0 0" xyz="0 0 0.5"/>
      <inertia ixx="0.8354166666666666" ixy="0.0" ixz="0.0" iyy="0.8354166666666666" iyz="0.0" izz="0.0041666666666666675"/>
    </inertial>
  </link>
  <gazebo reference="torso">
    <material>Gazebo/Black</material>
    <static>true</static>
  </gazebo>
  <!--
      Orbita3d

    link                      (joint)

    ${parent}                  (${name}_roll)
      ${name}_dummy_link1      (${name}_pitch)
        ${name}_dummy_link2    (${name}_yaw)
          ${name}_link         (${name}_ball_joint)
            ${name}_ball_link
    -->
  <link name="neck_dummy_link1">
    <inertial>
      <mass value="0.005"/>
      <origin rpy="0 0 0" xyz="0 0 0"/>
      <inertia ixx="2.5416666666666668e-06" ixy="0.0" ixz="0.0" iyy="2.5416666666666668e-06" iyz="0.0" izz="3e-06"/>
    </inertial>
  </link>
  <link name="neck_dummy_link2">
    <inertial>
      <mass value="0.005"/>
      <origin rpy="0 0 0" xyz="0 0 0"/>
      <inertia ixx="2.5416666666666668e-06" ixy="0.0" ixz="0.0" iyy="2.5416666666666668e-06" iyz="0.0" izz="3e-06"/>
    </inertial>
  </link>
  <link name="neck_link">
    <visual>
      <origin rpy="0 0 0" xyz="0 0 0.025"/>
      <geometry>
        <cylinder length="0.05" radius="0.03"/>
      </geometry>
      <material name="orbita3d_yellow">
        <color rgba="0.8 0.8 0.0 1"/>
      </material>
    </visual>
    <collision>
      <origin rpy="0 0 0" xyz="0 0 0.025"/>
      <geometry>
        <cylinder length="0.05" radius="0.03"/>
      </geometry>
    </collision>
    <inertial>
      <mass value="0.24"/>
      <origin rpy="0 0 0" xyz="0 0 -0.025"/>
      <inertia ixx="0.000122" ixy="0.0" ixz="0.0" iyy="0.000122" iyz="0.0" izz="0.000144"/>
    </inertial>
  </link>
  <link name="neck_ball_link">
    <visual>
      <origin rpy="0 0 0" xyz="0 0 0"/>
      <geometry>
        <sphere radius="0.036"/>
      </geometry>
      <material name="orbita3d_grey">
        <color rgba="0.8 0.8 0.8 1"/>
      </material>
    </visual>
    <collision>
      <origin rpy="0 0 0" xyz="0 0 0"/>
      <geometry>
        <sphere radius="0.036"/>
      </geometry>
    </collision>
    <inertial>
      <mass value="0.25"/>
      <origin xyz="0 0 0"/>
      <inertia ixx="0.00012959999999999998" ixy="0.0" ixz="0.0" iyy="0.00012959999999999998" iyz="0.0" izz="0.00012959999999999998"/>
    </inertial>
  </link>
  <joint name="neck_ball_joint" type="fixed">
    <origin rpy="0 0 0" xyz="0 0 0"/>
    <parent link="neck_link"/>
    <child link="neck_ball_link"/>
  </joint>
  <joint name="neck_roll" type="revolute">
    <origin rpy="0 0 0.0" xyz="-0.032893 0 0.110675"/>
    <parent link="torso"/>
    <child link="neck_dummy_link1"/>
    <axis xyz="1 0 0"/>
    <limit effort="1000.0" lower="-0.35" upper="0.35" velocity="100.0"/>
    <dynamics damping="0.1" friction="0.1"/>
  </joint>
  <joint name="neck_pitch" type="revolute">
    <origin rpy="0 0 0" xyz="0 0 0"/>
    <parent link="neck_dummy_link1"/>
    <child link="neck_dummy_link2"/>
    <axis xyz="0 1 0"/>
    <limit effort="1000.0" lower="-0.35" upper="0.35" velocity="100.0"/>
    <dynamics damping="0.1" friction="0.1"/>
  </joint>
  <joint name="neck_yaw" type="revolute">
    <origin rpy="0 0 0" xyz="0 0 0"/>
    <parent link="neck_dummy_link2"/>
    <child link="neck_link"/>
    <axis xyz="0 0 1"/>
    <limit effort="1000.0" lower="-1.57" upper="1.57" velocity="100.0"/>
    <dynamics damping="0.1" friction="0.1"/>
  </joint>
  <ros2_control name="neck" type="system">
    <hardware>
      <plugin>fake_components/GenericSystem</plugin>
    </hardware>
    <gpio name="neck">
      <state_interface name="torque">
        <param name="initial_value">0.0</param>
      </state_interface>
      <command_interface name="torque"/>
    </gpio>
    <joint name="neck_roll">
      <state_interface name="position">
        <param name="initial_value">0.0</param>
      </state_interface>
      <state_interface name="velocity">
        <param name="initial_value">0.0</param>
      </state_interface>
      <state_interface name="effort">
        <param name="initial_value">0.0</param>
      </state_interface>
      <command_interface name="position"/>
    </joint>
    <joint name="neck_pitch">
      <state_interface name="position">
        <param name="initial_value">0.0</param>
      </state_interface>
      <state_interface name="velocity">
        <param name="initial_value">0.0</param>
      </state_interface>
      <state_interface name="effort">
        <param name="initial_value">0.0</param>
      </state_interface>
      <command_interface name="position"/>
    </joint>
    <joint name="neck_yaw">
      <state_interface name="position">
        <param name="initial_value">0.0</param>
      </state_interface>
      <state_interface name="velocity">
        <param name="initial_value">0.0</param>
      </state_interface>
      <state_interface name="effort">
        <param name="initial_value">0.0</param>
      </state_interface>
      <command_interface name="position"/>
    </joint>
    <gpio name="neck_raw_motor_1">
      <state_interface name="speed_limit"/>
      <command_interface name="speed_limit"/>
      <state_interface name="torque_limit"/>
      <command_interface name="torque_limit"/>
      <state_interface name="p_gain"/>
      <command_interface name="p_gain"/>
      <state_interface name="i_gain"/>
      <command_interface name="i_gain"/>
      <state_interface name="d_gain"/>
      <command_interface name="d_gain"/>
    </gpio>
    <gpio name="neck_raw_motor_2">
      <state_interface name="speed_limit"/>
      <command_interface name="speed_limit"/>
      <state_interface name="torque_limit"/>
      <command_interface name="torque_limit"/>
      <state_interface name="p_gain"/>
      <command_interface name="p_gain"/>
      <state_interface name="i_gain"/>
      <command_interface name="i_gain"/>
      <state_interface name="d_gain"/>
      <command_interface name="d_gain"/>
    </gpio>
    <gpio name="neck_raw_motor_3">
      <state_interface name="speed_limit"/>
      <command_interface name="speed_limit"/>
      <state_interface name="torque_limit"/>
      <command_interface name="torque_limit"/>
      <state_interface name="p_gain"/>
      <command_interface name="p_gain"/>
      <state_interface name="i_gain"/>
      <command_interface name="i_gain"/>
      <state_interface name="d_gain"/>
      <command_interface name="d_gain"/>
    </gpio>
  </ros2_control>
  <joint name="neck_fixed" type="fixed">
    <origin rpy="0.0 0.0 0.0" xyz="0 0 0"/>
    <parent link="neck_ball_link"/>
    <child link="head"/>
  </joint>
  <!-- Head Links -->
  <link name="head">
    <inertial>
      <origin rpy="0.0 0.0 0.0" xyz="-0.009 -0.002 0.059"/>
      <mass value="0.237"/>
      <inertia ixx="1.676e-3" ixy="3.068e-6" ixz="1.2449e-4" iyy="1.368e-3" iyz="3.360e-5" izz="8.425e-4"/>
    </inertial>
    <visual name="">
      <origin rpy="0.0 0.0 0.0" xyz="0.0075 0.0 0.085"/>
      <geometry>
        <!-- <mesh filename="file://$(find reachy_description)/meshes/head.dae"/> -->
        <box size="0.015 0.1245 0.0265"/>
      </geometry>
      <material name="camblack"/>
    </visual>
    <collision>
      <origin rpy="0.0 0.0 0.0" xyz="0.0075 0.0 0.085"/>
      <geometry>
        <box size="0.015 0.1245 0.0265"/>
      </geometry>
    </collision>
  </link>
  <link name="head_base">
    <visual name="">
      <origin rpy="0.0 0.0 0.0" xyz="0.00 0.0 0.0425"/>
      <geometry>
        <cylinder length="0.07" radius="0.0225"/>
      </geometry>
      <material name="neckwhite"/>
    </visual>
  </link>
  <joint name="head_base_fixed" type="fixed">
    <origin rpy="0.0 0.0 0" xyz="0.0 0 0.0"/>
    <parent link="head"/>
    <child link="head_base"/>
  </joint>
  <!-- <link name="head_tracker"> -->
  <!--   <visual name=""> -->
  <!--     <origin xyz="0 0 0" rpy="0.0 0.0 0.0"/> -->
  <!--     <geometry> -->
  <!-- 	  <cylinder length="0.04" radius="0.04"/> -->
  <!--     </geometry> -->
  <!-- 	<material name="camblack"/> -->
  <!--   </visual> -->
  <!-- </link> -->
  <!-- <joint name="head_tracker_fixed" type="fixed"> -->
  <!--   <origin xyz="-0.030 0.0 0.111" rpy="0.0 0.0 0"/> -->
  <!--   <parent link="head" /> -->
  <!--   <child link="head_tracker" /> -->
  <!-- </joint> -->
  <link name="head_tip">
    </link>
  <joint name="head_tip_fixed" type="fixed">
    <!-- between the cameras -->
    <origin rpy="0 0.0 0" xyz="0.030 0.022 0.085"/>
    <!-- Rotation center -->
    <!-- <origin xyz="0.0 0 0.0" rpy="0.0 0.0 0"/> -->
    <parent link="head"/>
    <child link="head_tip"/>
  </joint>
  <link name="camera_optical_left">
    </link>
  <joint name="camera_optical_left" type="fixed">
    <!-- between the cameras -->
    <origin rpy="-1.57 0.0 -1.57" xyz="0.030 0.022 0.085"/>
    <!-- Rotation center -->
    <!-- <origin xyz="0.0 0 0.0" rpy="0.0 0.0 0"/> -->
    <parent link="head"/>
    <child link="camera_optical_left"/>
  </joint>
  <!-- Reachy Cameras -->
  <!-- URDF definition is so stupid we have to do that... -->
  <!-- <material name="gripperblack"> -->
  <!--     <color rgba="0.4 0.4 0.4 1"/> -->
  <!-- </material> -->
  <!-- <material name="gripperwhite"> -->
  <!--     <color rgba="0.9 0.9 0.9 1"/> -->
  <!-- </material> -->
  <!-- <material name="reachy_yellow"> -->
  <!--     <color rgba="0.8 0.8 0.0 1"/> -->
  <!-- </material> -->
  <!-- <material name="reachy_grey"> -->
  <!--     <color rgba="0.8 0.8 0.8 1"/> -->
  <!-- </material> -->
  <!-- <material name="reachy_metal"> -->
  <!--     <color rgba="0.85 0.85 0.85 1.0"/> -->
  <!-- </material> -->
  <!-- <material name="torsoblack"> -->
  <!--     <color rgba="0.5 0.5 0.5 1.0"/> -->
  <!-- </material> -->
  <!-- <material name="eyewhite"> -->
  <!--     <color rgba="1.0 1.0 1.0 1.0"/> -->
  <!-- </material> -->
  <!-- <material name="orbita2dmetal"> -->
  <!--     <color rgba="0.85 0.85 0.85 1.0"/> -->
  <!-- </material> -->
  <!-- <material name="orbita2dgrey"> -->
  <!--     <color rgba="0.8 0.8 0.8 1.0"/> -->
  <!-- </material> -->
  <!-- <material name="orbita3d_yellow"> -->
  <!--     <color rgba="0.8 0.8 0.0 1"/> -->
  <!-- </material> -->
  <!-- <material name="orbita3d_grey"> -->
  <!--     <color rgba="0.8 0.8 0.8 1"/> -->
  <!-- </material> -->
  <!-- URDF definition is so stupid we have to do that... -->
  <!-- <material name="gripperblack"> -->
  <!--     <color rgba="0.4 0.4 0.4 1"/> -->
  <!-- </material> -->
  <!-- <material name="gripperwhite"> -->
  <!--     <color rgba="0.9 0.9 0.9 1"/> -->
  <!-- </material> -->
  <!-- <material name="reachy_yellow"> -->
  <!--     <color rgba="0.8 0.8 0.0 1"/> -->
  <!-- </material> -->
  <!-- <material name="reachy_grey"> -->
  <!--     <color rgba="0.8 0.8 0.8 1"/> -->
  <!-- </material> -->
  <!-- <material name="reachy_metal"> -->
  <!--     <color rgba="0.85 0.85 0.85 1.0"/> -->
  <!-- </material> -->
  <!-- <material name="torsoblack"> -->
  <!--     <color rgba="0.5 0.5 0.5 1.0"/> -->
  <!-- </material> -->
  <!-- <material name="eyewhite"> -->
  <!--     <color rgba="1.0 1.0 1.0 1.0"/> -->
  <!-- </material> -->
  <!-- <material name="orbita2dmetal"> -->
  <!--     <color rgba="0.85 0.85 0.85 1.0"/> -->
  <!-- </material> -->
  <!-- <material name="orbita2dgrey"> -->
  <!--     <color rgba="0.8 0.8 0.8 1.0"/> -->
  <!-- </material> -->
  <!-- <material name="orbita3d_yellow"> -->
  <!--     <color rgba="0.8 0.8 0.0 1"/> -->
  <!-- </material> -->
  <!-- <material name="orbita3d_grey"> -->
  <!--     <color rgba="0.8 0.8 0.8 1"/> -->
  <!-- </material> -->
  <!-- <material name="orbita2dmetal"> -->
  <!--     <color rgba="0.85 0.85 0.85 1.0"/> -->
  <!-- </material> -->
  <!-- <material name="orbita2dgrey"> -->
  <!--     <color rgba="0.8 0.8 0.8 1.0"/> -->
  <!-- </material> -->
  <!-- <!-\- Orbita2d config -\-> -->
  <!-- <xacro:arg name="orbita2d_shoulder_config" default="$(find
    orbita2d_description)/config/fake.yaml"/> -->
  <!-- <xacro:arg name="orbita2d_elbow_config" default="$(find
    orbita2d_description)/config/fake.yaml"/> -->
  <!-- <!-\- Orbita3d config -\-> -->
  <!-- <xacro:arg name="orbita3d_wrist_config" default="$(find
    orbita3d_controller)/config/fake.yaml"/> -->
  <!-- ARM PARAMETERS -->
  <link name="r_virtual_offset"/>
  <joint name="r_virtual_joint" type="fixed">
    <origin rpy="-0.17453292519943295 0 0" xyz="0 0 0"/>
    <parent link="torso"/>
    <child link="r_virtual_offset"/>
  </joint>
  <!--
      Orbita 2 dof

    link                      (joint)

    ${parent}                 (${name}_joint1)
      ${name}_dummy_link      (${name}_joint2)
        ${name}_link          (${name}_ball_joint)
          ${name}_ball_link
    -->
  <link name="r_shoulder_dummy_link">
    <inertial>
      <mass value="0.005"/>
      <origin rpy="0 0 0" xyz="0 0 0"/>
      <inertia ixx="3.416666666666667e-05" ixy="0.0" ixz="0.0" iyy="3.416666666666667e-05" iyz="0.0" izz="3e-06"/>
    </inertial>
  </link>
  <joint name="r_shoulder_pitch" type="revolute">
    <origin rpy="0.17453292519943295 0 0.2617993877991494" xyz="0.0 -0.2 0.0"/>
    <parent link="r_virtual_offset"/>
    <child link="r_shoulder_dummy_link"/>
    <axis xyz="0 1 0"/>
    <limit effort="1000.0" lower="-1.5707963267948966" upper="1.5707963267948966" velocity="100.0"/>
    <safety_controller k_position="500" k_velocity="500" soft_lower_limit="-3.1415" soft_upper_limit="3.1415"/>
    <dynamics damping="0.1" friction="0.1"/>
  </joint>
  <link name="r_shoulder_link">
    <collision>
      <origin rpy="0 0 0" xyz="0 0 -0.14"/>
      <geometry>
        <!-- <cylinder length="${length}" radius="${radius}"/> -->
        <box size="0.075 0.06 0.28"/>
      </geometry>
    </collision>
    <visual>
      <origin rpy="0 0 0" xyz="0 0 -0.14"/>
      <geometry>
        <!-- <cylinder length="${length}" radius="${radius}"/> -->
        <box size="0.075 0.06 0.28"/>
      </geometry>
      <material name="orbita2dmetal">
        <color rgba="0.85 0.85 0.85 1.0"/>
      </material>
    </visual>
    <inertial>
      <mass value="0.245"/>
      <origin rpy="0 0 0" xyz="0 0 -0.14"/>
      <inertia ixx="0.001674166666666667" ixy="0.0" ixz="0.0" iyy="0.001674166666666667" iyz="0.0" izz="0.000147"/>
    </inertial>
  </link>
  <joint name="r_shoulder_roll" type="revolute">
    <origin rpy="0 0 0" xyz="0 0 0"/>
    <parent link="r_shoulder_dummy_link"/>
    <child link="r_shoulder_link"/>
    <axis xyz="1 0 0"/>
    <limit effort="1000.0" lower="-1.5707963267948966" upper="0.0" velocity="100.0"/>
    <safety_controller k_position="500" k_velocity="500" soft_lower_limit="-3.1415" soft_upper_limit="3.1415"/>
    <dynamics damping="0.1" friction="0.1"/>
  </joint>
  <gazebo reference="r_shoulder_link">
    <material>Gazebo/Orange</material>
  </gazebo>
  <link name="r_shoulder_ball_link">
    <visual>
      <origin rpy="0 0 0" xyz="0 0 0"/>
      <geometry>
        <sphere radius="0.036"/>
      </geometry>
      <material name="orbita2dgrey">
        <color rgba="0.8 0.8 0.8 1.0"/>
      </material>
    </visual>
    <collision>
      <origin rpy="0 0 0" xyz="0 0 0"/>
      <geometry>
        <sphere radius="0.036"/>
      </geometry>
    </collision>
    <inertial>
      <mass value="0.25"/>
      <origin xyz="0 0 0"/>
      <inertia ixx="0.00012959999999999998" ixy="0.0" ixz="0.0" iyy="0.00012959999999999998" iyz="0.0" izz="0.00012959999999999998"/>
    </inertial>
  </link>
  <joint name="r_shoulder_ball_joint" type="fixed">
    <origin rpy="0 0 0" xyz="0 0 0"/>
    <parent link="r_shoulder_link"/>
    <child link="r_shoulder_ball_link"/>
  </joint>
  <!--
      Orbita 2 dof

    link                      (joint)

    ${parent}                 (${name}_joint1)
      ${name}_dummy_link      (${name}_joint2)
        ${name}_link          (${name}_ball_joint)
          ${name}_ball_link
    -->
  <link name="r_elbow_dummy_link">
    <inertial>
      <mass value="0.0045000000000000005"/>
      <origin rpy="0 0 0" xyz="0 0 0"/>
      <inertia ixx="3.033750000000001e-05" ixy="0.0" ixz="0.0" iyy="3.033750000000001e-05" iyz="0.0" izz="1.8750000000000007e-06"/>
    </inertial>
  </link>
  <joint name="r_elbow_yaw" type="revolute">
    <origin rpy="0 0 -0.2617993877991494" xyz="0 0 -0.28"/>
    <parent link="r_shoulder_ball_link"/>
    <child link="r_elbow_dummy_link"/>
    <axis xyz="0 0 1"/>
    <limit effort="1000.0" lower="-1.5707963267948966" upper="1.5707963267948966" velocity="100.0"/>
    <safety_controller k_position="500" k_velocity="500" soft_lower_limit="-3.1415" soft_upper_limit="3.1415"/>
    <dynamics damping="0.1" friction="0.1"/>
  </joint>
  <link name="r_elbow_link">
    <collision>
      <origin rpy="0 0 0" xyz="0 0 -0.14"/>
      <geometry>
        <!-- <cylinder length="${length}" radius="${radius}"/> -->
        <box size="0.0625 0.05 0.28"/>
      </geometry>
    </collision>
    <visual>
      <origin rpy="0 0 0" xyz="0 0 -0.14"/>
      <geometry>
        <!-- <cylinder length="${length}" radius="${radius}"/> -->
        <box size="0.0625 0.05 0.28"/>
      </geometry>
      <material name="orbita2dmetal">
        <color rgba="0.85 0.85 0.85 1.0"/>
      </material>
    </visual>
    <inertial>
      <mass value="0.2205"/>
      <origin rpy="0 0 0" xyz="0 0 -0.14"/>
      <inertia ixx="0.0014865375000000002" ixy="0.0" ixz="0.0" iyy="0.0014865375000000002" iyz="0.0" izz="9.187500000000001e-05"/>
    </inertial>
  </link>
  <joint name="r_elbow_pitch" type="revolute">
    <origin rpy="0 0 0" xyz="0 0 0"/>
    <parent link="r_elbow_dummy_link"/>
    <child link="r_elbow_link"/>
    <axis xyz="0 1 0"/>
    <limit effort="1000.0" lower="-2.25" upper="0.1" velocity="100.0"/>
    <safety_controller k_position="500" k_velocity="500" soft_lower_limit="-3.1415" soft_upper_limit="3.1415"/>
    <dynamics damping="0.1" friction="0.1"/>
  </joint>
  <gazebo reference="r_elbow_link">
    <material>Gazebo/Orange</material>
  </gazebo>
  <link name="r_elbow_ball_link">
    <visual>
      <origin rpy="0 0 0" xyz="0 0 0"/>
      <geometry>
        <sphere radius="0.03"/>
      </geometry>
      <material name="orbita2dgrey">
        <color rgba="0.8 0.8 0.8 1.0"/>
      </material>
    </visual>
    <collision>
      <origin rpy="0 0 0" xyz="0 0 0"/>
      <geometry>
        <sphere radius="0.03"/>
      </geometry>
    </collision>
    <inertial>
      <mass value="0.225"/>
      <origin xyz="0 0 0"/>
      <inertia ixx="8.1e-05" ixy="0.0" ixz="0.0" iyy="8.1e-05" iyz="0.0" izz="8.1e-05"/>
    </inertial>
  </link>
  <joint name="r_elbow_ball_joint" type="fixed">
    <origin rpy="0 0 0" xyz="0 0 0"/>
    <parent link="r_elbow_link"/>
    <child link="r_elbow_ball_link"/>
  </joint>
  <!--
      Orbita3d

    link                      (joint)

    ${parent}                  (${name}_roll)
      ${name}_dummy_link1      (${name}_pitch)
        ${name}_dummy_link2    (${name}_yaw)
          ${name}_link         (${name}_ball_joint)
            ${name}_ball_link
    -->
  <link name="r_wrist_dummy_link1">
    <inertial>
      <mass value="0.003"/>
      <origin rpy="0 0 0" xyz="0 0 0"/>
      <inertia ixx="4.25e-07" ixy="0.0" ixz="0.0" iyy="4.25e-07" iyz="0.0" izz="8.000000000000001e-07"/>
    </inertial>
  </link>
  <link name="r_wrist_dummy_link2">
    <inertial>
      <mass value="0.003"/>
      <origin rpy="0 0 0" xyz="0 0 0"/>
      <inertia ixx="4.25e-07" ixy="0.0" ixz="0.0" iyy="4.25e-07" iyz="0.0" izz="8.000000000000001e-07"/>
    </inertial>
  </link>
  <link name="r_wrist_link">
    <visual>
      <origin rpy="0 0 0" xyz="0 0 0.005"/>
      <geometry>
        <cylinder length="0.01" radius="0.02"/>
      </geometry>
      <material name="orbita3d_yellow">
        <color rgba="0.8 0.8 0.0 1"/>
      </material>
    </visual>
    <collision>
      <origin rpy="0 0 0" xyz="0 0 0.005"/>
      <geometry>
        <cylinder length="0.01" radius="0.02"/>
      </geometry>
    </collision>
    <inertial>
      <mass value="0.144"/>
      <origin rpy="0 0 0" xyz="0 0 -0.005"/>
      <inertia ixx="2.0399999999999998e-05" ixy="0.0" ixz="0.0" iyy="2.0399999999999998e-05" iyz="0.0" izz="3.84e-05"/>
    </inertial>
  </link>
  <link name="r_wrist_ball_link">
    <visual>
      <origin rpy="0 0 0" xyz="0 0 0"/>
      <geometry>
        <sphere radius="0.024"/>
      </geometry>
      <material name="orbita3d_grey">
        <color rgba="0.8 0.8 0.8 1"/>
      </material>
    </visual>
    <collision>
      <origin rpy="0 0 0" xyz="0 0 0"/>
      <geometry>
        <sphere radius="0.024"/>
      </geometry>
    </collision>
    <inertial>
      <mass value="0.15"/>
      <origin xyz="0 0 0"/>
      <inertia ixx="3.456e-05" ixy="0.0" ixz="0.0" iyy="3.456e-05" iyz="0.0" izz="3.456e-05"/>
    </inertial>
  </link>
  <joint name="r_wrist_ball_joint" type="fixed">
    <origin rpy="0 0 0" xyz="0 0 0"/>
    <parent link="r_wrist_link"/>
    <child link="r_wrist_ball_link"/>
  </joint>
  <joint name="r_wrist_roll" type="revolute">
    <origin rpy="3.141592653589793 0 0" xyz="0 0 -0.28"/>
    <parent link="r_elbow_ball_link"/>
    <child link="r_wrist_dummy_link1"/>
    <axis xyz="1 0 0"/>
    <limit effort="1000.0" lower="-0.35" upper="0.35" velocity="100.0"/>
    <dynamics damping="0.1" friction="0.1"/>
  </joint>
  <joint name="r_wrist_pitch" type="revolute">
    <origin rpy="0 0 0" xyz="0 0 0"/>
    <parent link="r_wrist_dummy_link1"/>
    <child link="r_wrist_dummy_link2"/>
    <axis xyz="0 1 0"/>
    <limit effort="1000.0" lower="-0.35" upper="0.35" velocity="100.0"/>
    <dynamics damping="0.1" friction="0.1"/>
  </joint>
  <joint name="r_wrist_yaw" type="revolute">
    <origin rpy="0 0 0" xyz="0 0 0"/>
    <parent link="r_wrist_dummy_link2"/>
    <child link="r_wrist_link"/>
    <axis xyz="0 0 1"/>
    <limit effort="1000.0" lower="-1.57" upper="1.57" velocity="100.0"/>
    <dynamics damping="0.1" friction="0.1"/>
  </joint>
  <!-- URDF definition is so stupid we have to do that... -->
  <!-- <material name="gripperblack"> -->
  <!--     <color rgba="0.4 0.4 0.4 1"/> -->
  <!-- </material> -->
  <!-- <material name="gripperwhite"> -->
  <!--     <color rgba="0.9 0.9 0.9 1"/> -->
  <!-- </material> -->
  <!-- <material name="reachy_yellow"> -->
  <!--     <color rgba="0.8 0.8 0.0 1"/> -->
  <!-- </material> -->
  <!-- <material name="reachy_grey"> -->
  <!--     <color rgba="0.8 0.8 0.8 1"/> -->
  <!-- </material> -->
  <!-- <material name="reachy_metal"> -->
  <!--     <color rgba="0.85 0.85 0.85 1.0"/> -->
  <!-- </material> -->
  <!-- <material name="torsoblack"> -->
  <!--     <color rgba="0.5 0.5 0.5 1.0"/> -->
  <!-- </material> -->
  <!-- <material name="eyewhite"> -->
  <!--     <color rgba="1.0 1.0 1.0 1.0"/> -->
  <!-- </material> -->
  <!-- <material name="orbita2dmetal"> -->
  <!--     <color rgba="0.85 0.85 0.85 1.0"/> -->
  <!-- </material> -->
  <!-- <material name="orbita2dgrey"> -->
  <!--     <color rgba="0.8 0.8 0.8 1.0"/> -->
  <!-- </material> -->
  <!-- <material name="orbita3d_yellow"> -->
  <!--     <color rgba="0.8 0.8 0.0 1"/> -->
  <!-- </material> -->
  <!-- <material name="orbita3d_grey"> -->
  <!--     <color rgba="0.8 0.8 0.8 1"/> -->
  <!-- </material> -->
  <!-- <material name="gripperblack"> -->
  <!--     <color rgba="0.4 0.4 0.4 1"/> -->
  <!-- </material> -->
  <!-- <material name="gripperwhite"> -->
  <!--     <color rgba="0.9 0.9 0.9 1"/> -->
  <!-- </material> -->
  <link name="r_hand_palm_link">
    <collision>
      <origin rpy="0 0 0" xyz="0 0 0.03 "/>
      <geometry>
        <box size="0.03 0.06 0.06"/>
      </geometry>
    </collision>
    <visual>
      <origin rpy="0 0 0" xyz="0 0 0.03 "/>
      <geometry>
        <box size="0.03 0.06 0.06"/>
      </geometry>
      <material name="gripperblack">
        <color rgba="0.4 0.4 0.4 1"/>
      </material>
    </visual>
    <inertial>
      <mass value="0.2125"/>
      <origin rpy="0 0 0" xyz="0 0 0.03"/>
      <inertia ixx="0.00012749999999999998" ixy="0.0" ixz="0.0" iyy="7.968749999999999e-05" iyz="0.0" izz="7.968749999999999e-05"/>
    </inertial>
  </link>
  <joint name="r_hand_palm" type="fixed">
    <origin rpy="0.0 0 0.0" xyz="0 0 0"/>
    <parent link="r_wrist_ball_link"/>
    <child link="r_hand_palm_link"/>
  </joint>
  <link name="r_hand_index_link">
    <collision>
      <origin rpy="0 0 0" xyz="0 0 0.03 "/>
      <geometry>
        <box size="0.03 0.01 0.06"/>
      </geometry>
    </collision>
    <visual>
      <origin rpy="0 0 0" xyz="0 0 0.03 "/>
      <geometry>
        <box size="0.03 0.01 0.06"/>
      </geometry>
      <material name="gripperwhite">
        <color rgba="0.9 0.9 0.9 1"/>
      </material>
    </visual>
    <inertial>
      <mass value="0.025"/>
      <origin rpy="0 0 0" xyz="0 0.03 0.03"/>
      <inertia ixx="7.708333333333334e-06" ixy="0.0" ixz="0.0" iyy="9.375e-06" iyz="0.0" izz="2.0833333333333334e-06"/>
    </inertial>
  </link>
  <link name="r_hand_index_mimic_link">
    <collision>
      <origin rpy="0 0 0" xyz="0 0 0.03 "/>
      <geometry>
        <box size="0.03 0.01 0.06"/>
      </geometry>
    </collision>
    <visual>
      <origin rpy="0 0 0" xyz="0 0 0.03 "/>
      <geometry>
        <box size="0.03 0.01 0.06"/>
      </geometry>
      <material name="gripperwhite">
        <color rgba="0.9 0.9 0.9 1"/>
      </material>
    </visual>
    <inertial>
      <mass value="0.025"/>
      <origin rpy="0 0 0" xyz="0 0.03 0.03"/>
      <inertia ixx="7.708333333333334e-06" ixy="0.0" ixz="0.0" iyy="9.375e-06" iyz="0.0" izz="2.0833333333333334e-06"/>
    </inertial>
  </link>
  <joint name="r_hand_finger" type="revolute">
    <origin rpy="0 0 0" xyz="0 0.03 0.06"/>
    <parent link="r_hand_palm_link"/>
    <child link="r_hand_index_link"/>
    <axis xyz="1 0 0"/>
    <limit effort="1000.0" lower="-0.785" upper="2.094" velocity="0.0"/>
    <dynamics damping="0.1" friction="0.1"/>
  </joint>
  <joint name="r_hand_finger_mimic" type="revolute">
    <origin rpy="0 0 0" xyz="0 -0.03 0.06"/>
    <parent link="r_hand_palm_link"/>
    <child link="r_hand_index_mimic_link"/>
    <axis xyz="1 0 0"/>
    <limit effort="1000.0" lower="-0.785" upper="2.094" velocity="0.0"/>
    <dynamics damping="0.1" friction="0.1"/>
    <mimic joint="r_hand_finger" multiplier="-1" offset="0"/>
  </joint>
  <link name="r_arm_tip"/>
  <joint name="r_tip_joint" type="fixed">
    <origin rpy="3.141592653589793 0 0" xyz="0 0 0.1"/>
    <parent link="r_hand_palm_link"/>
    <child link="r_arm_tip"/>
  </joint>
  <ros2_control name="r_arm" type="system">
    <hardware>
      <!-- Use real hardware. -->
      <!-- <xacro:unless value="$(arg use_fake_hardware)"> -->
      <plugin>arm_system_hwi/ArmSystemHwi</plugin>
      <param name="config_file">/home/reachy/reachy_ws/install/arm_description/share/arm_description/config/fake_arm.yaml</param>
      <!-- </xacro:unless> -->
      <!-- <xacro:if value="$(arg use_fake_hardware)"> -->
      <!-- Use gazebo as hardware simulation. -->
      <!-- <xacro:if value="$(arg use_gazebo)"> -->
      <!-- <plugin>gazebo_ros2_control/GazeboSystem</plugin> -->
      <!-- </xacro:if> -->
      <!-- Use fake components. -->
      <!-- <xacro:unless value="$(arg use_gazebo)"> -->
      <!-- <plugin>fake_components/GenericSystem</plugin> -->
      <!-- </xacro:unless> -->
      <!-- </xacro:if> -->
    </hardware>
    <gpio name="r_shoulder">
      <state_interface name="torque">
        <param name="initial_value">0.0</param>
      </state_interface>
      <command_interface name="torque"/>
    </gpio>
    <joint name="r_shoulder_pitch">
      <state_interface name="position">
        <param name="initial_value">0.0</param>
      </state_interface>
      <state_interface name="velocity">
        <param name="initial_value">0.0</param>
      </state_interface>
      <state_interface name="effort">
        <param name="initial_value">0.0</param>
      </state_interface>
      <command_interface name="position"/>
    </joint>
    <joint name="r_shoulder_roll">
      <state_interface name="position">
        <param name="initial_value">0.0</param>
      </state_interface>
      <state_interface name="velocity">
        <param name="initial_value">0.0</param>
      </state_interface>
      <state_interface name="effort">
        <param name="initial_value">0.0</param>
      </state_interface>
      <command_interface name="position"/>
    </joint>
    <gpio name="r_shoulder_raw_motor_1">
      <state_interface name="speed_limit"/>
      <command_interface name="speed_limit"/>
      <state_interface name="torque_limit"/>
      <command_interface name="torque_limit"/>
      <state_interface name="p_gain"/>
      <command_interface name="p_gain"/>
      <state_interface name="i_gain"/>
      <command_interface name="i_gain"/>
      <state_interface name="d_gain"/>
      <command_interface name="d_gain"/>
    </gpio>
    <gpio name="r_shoulder_raw_motor_2">
      <state_interface name="speed_limit"/>
      <command_interface name="speed_limit"/>
      <state_interface name="torque_limit"/>
      <command_interface name="torque_limit"/>
      <state_interface name="p_gain"/>
      <command_interface name="p_gain"/>
      <state_interface name="i_gain"/>
      <command_interface name="i_gain"/>
      <state_interface name="d_gain"/>
      <command_interface name="d_gain"/>
    </gpio>
    <gpio name="r_elbow">
      <state_interface name="torque">
        <param name="initial_value">0.0</param>
      </state_interface>
      <command_interface name="torque"/>
    </gpio>
    <joint name="r_elbow_yaw">
      <state_interface name="position">
        <param name="initial_value">0.0</param>
      </state_interface>
      <state_interface name="velocity">
        <param name="initial_value">0.0</param>
      </state_interface>
      <state_interface name="effort">
        <param name="initial_value">0.0</param>
      </state_interface>
      <command_interface name="position"/>
    </joint>
    <joint name="r_elbow_pitch">
      <state_interface name="position">
        <param name="initial_value">0.0</param>
      </state_interface>
      <state_interface name="velocity">
        <param name="initial_value">0.0</param>
      </state_interface>
      <state_interface name="effort">
        <param name="initial_value">0.0</param>
      </state_interface>
      <command_interface name="position"/>
    </joint>
    <gpio name="r_elbow_raw_motor_1">
      <state_interface name="speed_limit"/>
      <command_interface name="speed_limit"/>
      <state_interface name="torque_limit"/>
      <command_interface name="torque_limit"/>
      <state_interface name="p_gain"/>
      <command_interface name="p_gain"/>
      <state_interface name="i_gain"/>
      <command_interface name="i_gain"/>
      <state_interface name="d_gain"/>
      <command_interface name="d_gain"/>
    </gpio>
    <gpio name="r_elbow_raw_motor_2">
      <state_interface name="speed_limit"/>
      <command_interface name="speed_limit"/>
      <state_interface name="torque_limit"/>
      <command_interface name="torque_limit"/>
      <state_interface name="p_gain"/>
      <command_interface name="p_gain"/>
      <state_interface name="i_gain"/>
      <command_interface name="i_gain"/>
      <state_interface name="d_gain"/>
      <command_interface name="d_gain"/>
    </gpio>
    <gpio name="r_wrist">
      <state_interface name="torque">
        <param name="initial_value">0.0</param>
      </state_interface>
      <command_interface name="torque"/>
    </gpio>
    <joint name="r_wrist_roll">
      <state_interface name="position">
        <param name="initial_value">0.0</param>
      </state_interface>
      <state_interface name="velocity">
        <param name="initial_value">0.0</param>
      </state_interface>
      <state_interface name="effort">
        <param name="initial_value">0.0</param>
      </state_interface>
      <command_interface name="position"/>
    </joint>
    <joint name="r_wrist_pitch">
      <state_interface name="position">
        <param name="initial_value">0.0</param>
      </state_interface>
      <state_interface name="velocity">
        <param name="initial_value">0.0</param>
      </state_interface>
      <state_interface name="effort">
        <param name="initial_value">0.0</param>
      </state_interface>
      <command_interface name="position"/>
    </joint>
    <joint name="r_wrist_yaw">
      <state_interface name="position">
        <param name="initial_value">0.0</param>
      </state_interface>
      <state_interface name="velocity">
        <param name="initial_value">0.0</param>
      </state_interface>
      <state_interface name="effort">
        <param name="initial_value">0.0</param>
      </state_interface>
      <command_interface name="position"/>
    </joint>
    <gpio name="r_wrist_raw_motor_1">
      <state_interface name="speed_limit"/>
      <command_interface name="speed_limit"/>
      <state_interface name="torque_limit"/>
      <command_interface name="torque_limit"/>
      <state_interface name="p_gain"/>
      <command_interface name="p_gain"/>
      <state_interface name="i_gain"/>
      <command_interface name="i_gain"/>
      <state_interface name="d_gain"/>
      <command_interface name="d_gain"/>
    </gpio>
    <gpio name="r_wrist_raw_motor_2">
      <state_interface name="speed_limit"/>
      <command_interface name="speed_limit"/>
      <state_interface name="torque_limit"/>
      <command_interface name="torque_limit"/>
      <state_interface name="p_gain"/>
      <command_interface name="p_gain"/>
      <state_interface name="i_gain"/>
      <command_interface name="i_gain"/>
      <state_interface name="d_gain"/>
      <command_interface name="d_gain"/>
    </gpio>
    <gpio name="r_wrist_raw_motor_3">
      <state_interface name="speed_limit"/>
      <command_interface name="speed_limit"/>
      <state_interface name="torque_limit"/>
      <command_interface name="torque_limit"/>
      <state_interface name="p_gain"/>
      <command_interface name="p_gain"/>
      <state_interface name="i_gain"/>
      <command_interface name="i_gain"/>
      <state_interface name="d_gain"/>
      <command_interface name="d_gain"/>
    </gpio>
    <gpio name="r_hand">
      <state_interface name="torque">
        <param name="initial_value">0.0</param>
      </state_interface>
      <command_interface name="torque"/>
    </gpio>
    <joint name="r_hand_finger">
      <state_interface name="position">
        <param name="initial_value">0.0</param>
      </state_interface>
      <state_interface name="velocity">
        <param name="initial_value">0.0</param>
      </state_interface>
      <state_interface name="effort">
        <param name="initial_value">0.0</param>
      </state_interface>
      <command_interface name="position"/>
    </joint>
    <gpio name="r_hand_raw_motor_1">
      <state_interface name="speed_limit"/>
      <command_interface name="speed_limit"/>
      <state_interface name="torque_limit"/>
      <command_interface name="torque_limit"/>
      <state_interface name="p_gain"/>
      <command_interface name="p_gain"/>
      <state_interface name="i_gain"/>
      <command_interface name="i_gain"/>
      <state_interface name="d_gain"/>
      <command_interface name="d_gain"/>
    </gpio>
  </ros2_control>
  <!-- URDF definition is so stupid we have to do that... -->
  <!-- <material name="gripperblack"> -->
  <!--     <color rgba="0.4 0.4 0.4 1"/> -->
  <!-- </material> -->
  <!-- <material name="gripperwhite"> -->
  <!--     <color rgba="0.9 0.9 0.9 1"/> -->
  <!-- </material> -->
  <!-- <material name="reachy_yellow"> -->
  <!--     <color rgba="0.8 0.8 0.0 1"/> -->
  <!-- </material> -->
  <!-- <material name="reachy_grey"> -->
  <!--     <color rgba="0.8 0.8 0.8 1"/> -->
  <!-- </material> -->
  <!-- <material name="reachy_metal"> -->
  <!--     <color rgba="0.85 0.85 0.85 1.0"/> -->
  <!-- </material> -->
  <!-- <material name="torsoblack"> -->
  <!--     <color rgba="0.5 0.5 0.5 1.0"/> -->
  <!-- </material> -->
  <!-- <material name="eyewhite"> -->
  <!--     <color rgba="1.0 1.0 1.0 1.0"/> -->
  <!-- </material> -->
  <!-- <material name="orbita2dmetal"> -->
  <!--     <color rgba="0.85 0.85 0.85 1.0"/> -->
  <!-- </material> -->
  <!-- <material name="orbita2dgrey"> -->
  <!--     <color rgba="0.8 0.8 0.8 1.0"/> -->
  <!-- </material> -->
  <!-- <material name="orbita3d_yellow"> -->
  <!--     <color rgba="0.8 0.8 0.0 1"/> -->
  <!-- </material> -->
  <!-- <material name="orbita3d_grey"> -->
  <!--     <color rgba="0.8 0.8 0.8 1"/> -->
  <!-- </material> -->
  <!-- URDF definition is so stupid we have to do that... -->
  <!-- <material name="gripperblack"> -->
  <!--     <color rgba="0.4 0.4 0.4 1"/> -->
  <!-- </material> -->
  <!-- <material name="gripperwhite"> -->
  <!--     <color rgba="0.9 0.9 0.9 1"/> -->
  <!-- </material> -->
  <!-- <material name="reachy_yellow"> -->
  <!--     <color rgba="0.8 0.8 0.0 1"/> -->
  <!-- </material> -->
  <!-- <material name="reachy_grey"> -->
  <!--     <color rgba="0.8 0.8 0.8 1"/> -->
  <!-- </material> -->
  <!-- <material name="reachy_metal"> -->
  <!--     <color rgba="0.85 0.85 0.85 1.0"/> -->
  <!-- </material> -->
  <!-- <material name="torsoblack"> -->
  <!--     <color rgba="0.5 0.5 0.5 1.0"/> -->
  <!-- </material> -->
  <!-- <material name="eyewhite"> -->
  <!--     <color rgba="1.0 1.0 1.0 1.0"/> -->
  <!-- </material> -->
  <!-- <material name="orbita2dmetal"> -->
  <!--     <color rgba="0.85 0.85 0.85 1.0"/> -->
  <!-- </material> -->
  <!-- <material name="orbita2dgrey"> -->
  <!--     <color rgba="0.8 0.8 0.8 1.0"/> -->
  <!-- </material> -->
  <!-- <material name="orbita3d_yellow"> -->
  <!--     <color rgba="0.8 0.8 0.0 1"/> -->
  <!-- </material> -->
  <!-- <material name="orbita3d_grey"> -->
  <!--     <color rgba="0.8 0.8 0.8 1"/> -->
  <!-- </material> -->
  <!-- <material name="orbita2dmetal"> -->
  <!--     <color rgba="0.85 0.85 0.85 1.0"/> -->
  <!-- </material> -->
  <!-- <material name="orbita2dgrey"> -->
  <!--     <color rgba="0.8 0.8 0.8 1.0"/> -->
  <!-- </material> -->
  <!-- <!-\- Orbita2d config -\-> -->
  <!-- <xacro:arg name="orbita2d_shoulder_config" default="$(find
    orbita2d_description)/config/fake.yaml"/> -->
  <!-- <xacro:arg name="orbita2d_elbow_config" default="$(find
    orbita2d_description)/config/fake.yaml"/> -->
  <!-- <!-\- Orbita3d config -\-> -->
  <!-- <xacro:arg name="orbita3d_wrist_config" default="$(find
    orbita3d_controller)/config/fake.yaml"/> -->
  <!-- ARM PARAMETERS -->
  <link name="l_virtual_offset"/>
  <joint name="l_virtual_joint" type="fixed">
    <origin rpy="0.17453292519943295 0 0" xyz="0 0 0"/>
    <parent link="torso"/>
    <child link="l_virtual_offset"/>
  </joint>
  <!--
      Orbita 2 dof

    link                      (joint)

    ${parent}                 (${name}_joint1)
      ${name}_dummy_link      (${name}_joint2)
        ${name}_link          (${name}_ball_joint)
          ${name}_ball_link
    -->
  <link name="l_shoulder_dummy_link">
    <inertial>
      <mass value="0.005"/>
      <origin rpy="0 0 0" xyz="0 0 0"/>
      <inertia ixx="3.416666666666667e-05" ixy="0.0" ixz="0.0" iyy="3.416666666666667e-05" iyz="0.0" izz="3e-06"/>
    </inertial>
  </link>
  <joint name="l_shoulder_pitch" type="revolute">
    <origin rpy="-0.17453292519943295 0 -0.2617993877991494" xyz="0.0 0.2 0.0"/>
    <parent link="l_virtual_offset"/>
    <child link="l_shoulder_dummy_link"/>
    <axis xyz="0 1 0"/>
    <limit effort="1000.0" lower="-1.5707963267948966" upper="1.5707963267948966" velocity="100.0"/>
    <safety_controller k_position="500" k_velocity="500" soft_lower_limit="-3.1415" soft_upper_limit="3.1415"/>
    <dynamics damping="0.1" friction="0.1"/>
  </joint>
  <link name="l_shoulder_link">
    <collision>
      <origin rpy="0 0 0" xyz="0 0 -0.14"/>
      <geometry>
        <!-- <cylinder length="${length}" radius="${radius}"/> -->
        <box size="0.075 0.06 0.28"/>
      </geometry>
    </collision>
    <visual>
      <origin rpy="0 0 0" xyz="0 0 -0.14"/>
      <geometry>
        <!-- <cylinder length="${length}" radius="${radius}"/> -->
        <box size="0.075 0.06 0.28"/>
      </geometry>
      <material name="orbita2dmetal">
        <color rgba="0.85 0.85 0.85 1.0"/>
      </material>
    </visual>
    <inertial>
      <mass value="0.245"/>
      <origin rpy="0 0 0" xyz="0 0 -0.14"/>
      <inertia ixx="0.001674166666666667" ixy="0.0" ixz="0.0" iyy="0.001674166666666667" iyz="0.0" izz="0.000147"/>
    </inertial>
  </link>
  <joint name="l_shoulder_roll" type="revolute">
    <origin rpy="0 0 0" xyz="0 0 0"/>
    <parent link="l_shoulder_dummy_link"/>
    <child link="l_shoulder_link"/>
    <axis xyz="1 0 0"/>
    <limit effort="1000.0" lower="-1.5707963267948966" upper="0.0" velocity="100.0"/>
    <safety_controller k_position="500" k_velocity="500" soft_lower_limit="-3.1415" soft_upper_limit="3.1415"/>
    <dynamics damping="0.1" friction="0.1"/>
  </joint>
  <gazebo reference="l_shoulder_link">
    <material>Gazebo/Orange</material>
  </gazebo>
  <link name="l_shoulder_ball_link">
    <visual>
      <origin rpy="0 0 0" xyz="0 0 0"/>
      <geometry>
        <sphere radius="0.036"/>
      </geometry>
      <material name="orbita2dgrey">
        <color rgba="0.8 0.8 0.8 1.0"/>
      </material>
    </visual>
    <collision>
      <origin rpy="0 0 0" xyz="0 0 0"/>
      <geometry>
        <sphere radius="0.036"/>
      </geometry>
    </collision>
    <inertial>
      <mass value="0.25"/>
      <origin xyz="0 0 0"/>
      <inertia ixx="0.00012959999999999998" ixy="0.0" ixz="0.0" iyy="0.00012959999999999998" iyz="0.0" izz="0.00012959999999999998"/>
    </inertial>
  </link>
  <joint name="l_shoulder_ball_joint" type="fixed">
    <origin rpy="0 0 0" xyz="0 0 0"/>
    <parent link="l_shoulder_link"/>
    <child link="l_shoulder_ball_link"/>
  </joint>
  <!--
      Orbita 2 dof

    link                      (joint)

    ${parent}                 (${name}_joint1)
      ${name}_dummy_link      (${name}_joint2)
        ${name}_link          (${name}_ball_joint)
          ${name}_ball_link
    -->
  <link name="l_elbow_dummy_link">
    <inertial>
      <mass value="0.0045000000000000005"/>
      <origin rpy="0 0 0" xyz="0 0 0"/>
      <inertia ixx="3.033750000000001e-05" ixy="0.0" ixz="0.0" iyy="3.033750000000001e-05" iyz="0.0" izz="1.8750000000000007e-06"/>
    </inertial>
  </link>
  <joint name="l_elbow_yaw" type="revolute">
    <origin rpy="0 0 0.2617993877991494" xyz="0 0 -0.28"/>
    <parent link="l_shoulder_ball_link"/>
    <child link="l_elbow_dummy_link"/>
    <axis xyz="0 0 1"/>
    <limit effort="1000.0" lower="-1.5707963267948966" upper="1.5707963267948966" velocity="100.0"/>
    <safety_controller k_position="500" k_velocity="500" soft_lower_limit="-3.1415" soft_upper_limit="3.1415"/>
    <dynamics damping="0.1" friction="0.1"/>
  </joint>
  <link name="l_elbow_link">
    <collision>
      <origin rpy="0 0 0" xyz="0 0 -0.14"/>
      <geometry>
        <!-- <cylinder length="${length}" radius="${radius}"/> -->
        <box size="0.0625 0.05 0.28"/>
      </geometry>
    </collision>
    <visual>
      <origin rpy="0 0 0" xyz="0 0 -0.14"/>
      <geometry>
        <!-- <cylinder length="${length}" radius="${radius}"/> -->
        <box size="0.0625 0.05 0.28"/>
      </geometry>
      <material name="orbita2dmetal">
        <color rgba="0.85 0.85 0.85 1.0"/>
      </material>
    </visual>
    <inertial>
      <mass value="0.2205"/>
      <origin rpy="0 0 0" xyz="0 0 -0.14"/>
      <inertia ixx="0.0014865375000000002" ixy="0.0" ixz="0.0" iyy="0.0014865375000000002" iyz="0.0" izz="9.187500000000001e-05"/>
    </inertial>
  </link>
  <joint name="l_elbow_pitch" type="revolute">
    <origin rpy="0 0 0" xyz="0 0 0"/>
    <parent link="l_elbow_dummy_link"/>
    <child link="l_elbow_link"/>
    <axis xyz="0 1 0"/>
    <limit effort="1000.0" lower="-2.25" upper="0.1" velocity="100.0"/>
    <safety_controller k_position="500" k_velocity="500" soft_lower_limit="-3.1415" soft_upper_limit="3.1415"/>
    <dynamics damping="0.1" friction="0.1"/>
  </joint>
  <gazebo reference="l_elbow_link">
    <material>Gazebo/Orange</material>
  </gazebo>
  <link name="l_elbow_ball_link">
    <visual>
      <origin rpy="0 0 0" xyz="0 0 0"/>
      <geometry>
        <sphere radius="0.03"/>
      </geometry>
      <material name="orbita2dgrey">
        <color rgba="0.8 0.8 0.8 1.0"/>
      </material>
    </visual>
    <collision>
      <origin rpy="0 0 0" xyz="0 0 0"/>
      <geometry>
        <sphere radius="0.03"/>
      </geometry>
    </collision>
    <inertial>
      <mass value="0.225"/>
      <origin xyz="0 0 0"/>
      <inertia ixx="8.1e-05" ixy="0.0" ixz="0.0" iyy="8.1e-05" iyz="0.0" izz="8.1e-05"/>
    </inertial>
  </link>
  <joint name="l_elbow_ball_joint" type="fixed">
    <origin rpy="0 0 0" xyz="0 0 0"/>
    <parent link="l_elbow_link"/>
    <child link="l_elbow_ball_link"/>
  </joint>
  <!--
      Orbita3d

    link                      (joint)

    ${parent}                  (${name}_roll)
      ${name}_dummy_link1      (${name}_pitch)
        ${name}_dummy_link2    (${name}_yaw)
          ${name}_link         (${name}_ball_joint)
            ${name}_ball_link
    -->
  <link name="l_wrist_dummy_link1">
    <inertial>
      <mass value="0.003"/>
      <origin rpy="0 0 0" xyz="0 0 0"/>
      <inertia ixx="4.25e-07" ixy="0.0" ixz="0.0" iyy="4.25e-07" iyz="0.0" izz="8.000000000000001e-07"/>
    </inertial>
  </link>
  <link name="l_wrist_dummy_link2">
    <inertial>
      <mass value="0.003"/>
      <origin rpy="0 0 0" xyz="0 0 0"/>
      <inertia ixx="4.25e-07" ixy="0.0" ixz="0.0" iyy="4.25e-07" iyz="0.0" izz="8.000000000000001e-07"/>
    </inertial>
  </link>
  <link name="l_wrist_link">
    <visual>
      <origin rpy="0 0 0" xyz="0 0 0.005"/>
      <geometry>
        <cylinder length="0.01" radius="0.02"/>
      </geometry>
      <material name="orbita3d_yellow">
        <color rgba="0.8 0.8 0.0 1"/>
      </material>
    </visual>
    <collision>
      <origin rpy="0 0 0" xyz="0 0 0.005"/>
      <geometry>
        <cylinder length="0.01" radius="0.02"/>
      </geometry>
    </collision>
    <inertial>
      <mass value="0.144"/>
      <origin rpy="0 0 0" xyz="0 0 -0.005"/>
      <inertia ixx="2.0399999999999998e-05" ixy="0.0" ixz="0.0" iyy="2.0399999999999998e-05" iyz="0.0" izz="3.84e-05"/>
    </inertial>
  </link>
  <link name="l_wrist_ball_link">
    <visual>
      <origin rpy="0 0 0" xyz="0 0 0"/>
      <geometry>
        <sphere radius="0.024"/>
      </geometry>
      <material name="orbita3d_grey">
        <color rgba="0.8 0.8 0.8 1"/>
      </material>
    </visual>
    <collision>
      <origin rpy="0 0 0" xyz="0 0 0"/>
      <geometry>
        <sphere radius="0.024"/>
      </geometry>
    </collision>
    <inertial>
      <mass value="0.15"/>
      <origin xyz="0 0 0"/>
      <inertia ixx="3.456e-05" ixy="0.0" ixz="0.0" iyy="3.456e-05" iyz="0.0" izz="3.456e-05"/>
    </inertial>
  </link>
  <joint name="l_wrist_ball_joint" type="fixed">
    <origin rpy="0 0 0" xyz="0 0 0"/>
    <parent link="l_wrist_link"/>
    <child link="l_wrist_ball_link"/>
  </joint>
  <joint name="l_wrist_roll" type="revolute">
    <origin rpy="3.141592653589793 0 0" xyz="0 0 -0.28"/>
    <parent link="l_elbow_ball_link"/>
    <child link="l_wrist_dummy_link1"/>
    <axis xyz="1 0 0"/>
    <limit effort="1000.0" lower="-0.35" upper="0.35" velocity="100.0"/>
    <dynamics damping="0.1" friction="0.1"/>
  </joint>
  <joint name="l_wrist_pitch" type="revolute">
    <origin rpy="0 0 0" xyz="0 0 0"/>
    <parent link="l_wrist_dummy_link1"/>
    <child link="l_wrist_dummy_link2"/>
    <axis xyz="0 1 0"/>
    <limit effort="1000.0" lower="-0.35" upper="0.35" velocity="100.0"/>
    <dynamics damping="0.1" friction="0.1"/>
  </joint>
  <joint name="l_wrist_yaw" type="revolute">
    <origin rpy="0 0 0" xyz="0 0 0"/>
    <parent link="l_wrist_dummy_link2"/>
    <child link="l_wrist_link"/>
    <axis xyz="0 0 1"/>
    <limit effort="1000.0" lower="-1.57" upper="1.57" velocity="100.0"/>
    <dynamics damping="0.1" friction="0.1"/>
  </joint>
  <!-- URDF definition is so stupid we have to do that... -->
  <!-- <material name="gripperblack"> -->
  <!--     <color rgba="0.4 0.4 0.4 1"/> -->
  <!-- </material> -->
  <!-- <material name="gripperwhite"> -->
  <!--     <color rgba="0.9 0.9 0.9 1"/> -->
  <!-- </material> -->
  <!-- <material name="reachy_yellow"> -->
  <!--     <color rgba="0.8 0.8 0.0 1"/> -->
  <!-- </material> -->
  <!-- <material name="reachy_grey"> -->
  <!--     <color rgba="0.8 0.8 0.8 1"/> -->
  <!-- </material> -->
  <!-- <material name="reachy_metal"> -->
  <!--     <color rgba="0.85 0.85 0.85 1.0"/> -->
  <!-- </material> -->
  <!-- <material name="torsoblack"> -->
  <!--     <color rgba="0.5 0.5 0.5 1.0"/> -->
  <!-- </material> -->
  <!-- <material name="eyewhite"> -->
  <!--     <color rgba="1.0 1.0 1.0 1.0"/> -->
  <!-- </material> -->
  <!-- <material name="orbita2dmetal"> -->
  <!--     <color rgba="0.85 0.85 0.85 1.0"/> -->
  <!-- </material> -->
  <!-- <material name="orbita2dgrey"> -->
  <!--     <color rgba="0.8 0.8 0.8 1.0"/> -->
  <!-- </material> -->
  <!-- <material name="orbita3d_yellow"> -->
  <!--     <color rgba="0.8 0.8 0.0 1"/> -->
  <!-- </material> -->
  <!-- <material name="orbita3d_grey"> -->
  <!--     <color rgba="0.8 0.8 0.8 1"/> -->
  <!-- </material> -->
  <!-- <material name="gripperblack"> -->
  <!--     <color rgba="0.4 0.4 0.4 1"/> -->
  <!-- </material> -->
  <!-- <material name="gripperwhite"> -->
  <!--     <color rgba="0.9 0.9 0.9 1"/> -->
  <!-- </material> -->
  <link name="l_hand_palm_link">
    <collision>
      <origin rpy="0 0 0" xyz="0 0 0.03 "/>
      <geometry>
        <box size="0.03 0.06 0.06"/>
      </geometry>
    </collision>
    <visual>
      <origin rpy="0 0 0" xyz="0 0 0.03 "/>
      <geometry>
        <box size="0.03 0.06 0.06"/>
      </geometry>
      <material name="gripperblack">
        <color rgba="0.4 0.4 0.4 1"/>
      </material>
    </visual>
    <inertial>
      <mass value="0.2125"/>
      <origin rpy="0 0 0" xyz="0 0 0.03"/>
      <inertia ixx="0.00012749999999999998" ixy="0.0" ixz="0.0" iyy="7.968749999999999e-05" iyz="0.0" izz="7.968749999999999e-05"/>
    </inertial>
  </link>
  <joint name="l_hand_palm" type="fixed">
    <origin rpy="0.0 0 0.0" xyz="0 0 0"/>
    <parent link="l_wrist_ball_link"/>
    <child link="l_hand_palm_link"/>
  </joint>
  <link name="l_hand_index_link">
    <collision>
      <origin rpy="0 0 0" xyz="0 0 0.03 "/>
      <geometry>
        <box size="0.03 0.01 0.06"/>
      </geometry>
    </collision>
    <visual>
      <origin rpy="0 0 0" xyz="0 0 0.03 "/>
      <geometry>
        <box size="0.03 0.01 0.06"/>
      </geometry>
      <material name="gripperwhite">
        <color rgba="0.9 0.9 0.9 1"/>
      </material>
    </visual>
    <inertial>
      <mass value="0.025"/>
      <origin rpy="0 0 0" xyz="0 0.03 0.03"/>
      <inertia ixx="7.708333333333334e-06" ixy="0.0" ixz="0.0" iyy="9.375e-06" iyz="0.0" izz="2.0833333333333334e-06"/>
    </inertial>
  </link>
  <link name="l_hand_index_mimic_link">
    <collision>
      <origin rpy="0 0 0" xyz="0 0 0.03 "/>
      <geometry>
        <box size="0.03 0.01 0.06"/>
      </geometry>
    </collision>
    <visual>
      <origin rpy="0 0 0" xyz="0 0 0.03 "/>
      <geometry>
        <box size="0.03 0.01 0.06"/>
      </geometry>
      <material name="gripperwhite">
        <color rgba="0.9 0.9 0.9 1"/>
      </material>
    </visual>
    <inertial>
      <mass value="0.025"/>
      <origin rpy="0 0 0" xyz="0 0.03 0.03"/>
      <inertia ixx="7.708333333333334e-06" ixy="0.0" ixz="0.0" iyy="9.375e-06" iyz="0.0" izz="2.0833333333333334e-06"/>
    </inertial>
  </link>
  <joint name="l_hand_finger" type="revolute">
    <origin rpy="0 0 0" xyz="0 -0.03 0.06"/>
    <parent link="l_hand_palm_link"/>
    <child link="l_hand_index_link"/>
    <axis xyz="1 0 0"/>
    <limit effort="1000.0" lower="-2.094" upper="0.785" velocity="0.0"/>
    <dynamics damping="0.1" friction="0.1"/>
  </joint>
  <joint name="l_hand_finger_mimic" type="revolute">
    <origin rpy="0 0 0" xyz="0 0.03 0.06"/>
    <parent link="l_hand_palm_link"/>
    <child link="l_hand_index_mimic_link"/>
    <axis xyz="1 0 0"/>
    <limit effort="1000.0" lower="-2.094" upper="0.785" velocity="0.0"/>
    <dynamics damping="0.1" friction="0.1"/>
    <mimic joint="l_hand_finger" multiplier="-1" offset="0"/>
  </joint>
  <link name="l_arm_tip"/>
  <joint name="l_tip_joint" type="fixed">
    <origin rpy="3.141592653589793 0 0" xyz="0 0 0.1"/>
    <parent link="l_hand_palm_link"/>
    <child link="l_arm_tip"/>
  </joint>
  <ros2_control name="l_arm" type="system">
    <hardware>
      <!-- Use real hardware. -->
      <!-- <xacro:unless value="$(arg use_fake_hardware)"> -->
      <plugin>arm_system_hwi/ArmSystemHwi</plugin>
      <param name="config_file">/home/reachy/reachy_ws/install/arm_description/share/arm_description/config/fake_arm.yaml</param>
      <!-- </xacro:unless> -->
      <!-- <xacro:if value="$(arg use_fake_hardware)"> -->
      <!-- Use gazebo as hardware simulation. -->
      <!-- <xacro:if value="$(arg use_gazebo)"> -->
      <!-- <plugin>gazebo_ros2_control/GazeboSystem</plugin> -->
      <!-- </xacro:if> -->
      <!-- Use fake components. -->
      <!-- <xacro:unless value="$(arg use_gazebo)"> -->
      <!-- <plugin>fake_components/GenericSystem</plugin> -->
      <!-- </xacro:unless> -->
      <!-- </xacro:if> -->
    </hardware>
    <gpio name="l_shoulder">
      <state_interface name="torque">
        <param name="initial_value">0.0</param>
      </state_interface>
      <command_interface name="torque"/>
    </gpio>
    <joint name="l_shoulder_pitch">
      <state_interface name="position">
        <param name="initial_value">0.0</param>
      </state_interface>
      <state_interface name="velocity">
        <param name="initial_value">0.0</param>
      </state_interface>
      <state_interface name="effort">
        <param name="initial_value">0.0</param>
      </state_interface>
      <command_interface name="position"/>
    </joint>
    <joint name="l_shoulder_roll">
      <state_interface name="position">
        <param name="initial_value">0.0</param>
      </state_interface>
      <state_interface name="velocity">
        <param name="initial_value">0.0</param>
      </state_interface>
      <state_interface name="effort">
        <param name="initial_value">0.0</param>
      </state_interface>
      <command_interface name="position"/>
    </joint>
    <gpio name="l_shoulder_raw_motor_1">
      <state_interface name="speed_limit"/>
      <command_interface name="speed_limit"/>
      <state_interface name="torque_limit"/>
      <command_interface name="torque_limit"/>
      <state_interface name="p_gain"/>
      <command_interface name="p_gain"/>
      <state_interface name="i_gain"/>
      <command_interface name="i_gain"/>
      <state_interface name="d_gain"/>
      <command_interface name="d_gain"/>
    </gpio>
    <gpio name="l_shoulder_raw_motor_2">
      <state_interface name="speed_limit"/>
      <command_interface name="speed_limit"/>
      <state_interface name="torque_limit"/>
      <command_interface name="torque_limit"/>
      <state_interface name="p_gain"/>
      <command_interface name="p_gain"/>
      <state_interface name="i_gain"/>
      <command_interface name="i_gain"/>
      <state_interface name="d_gain"/>
      <command_interface name="d_gain"/>
    </gpio>
    <gpio name="l_elbow">
      <state_interface name="torque">
        <param name="initial_value">0.0</param>
      </state_interface>
      <command_interface name="torque"/>
    </gpio>
    <joint name="l_elbow_yaw">
      <state_interface name="position">
        <param name="initial_value">0.0</param>
      </state_interface>
      <state_interface name="velocity">
        <param name="initial_value">0.0</param>
      </state_interface>
      <state_interface name="effort">
        <param name="initial_value">0.0</param>
      </state_interface>
      <command_interface name="position"/>
    </joint>
    <joint name="l_elbow_pitch">
      <state_interface name="position">
        <param name="initial_value">0.0</param>
      </state_interface>
      <state_interface name="velocity">
        <param name="initial_value">0.0</param>
      </state_interface>
      <state_interface name="effort">
        <param name="initial_value">0.0</param>
      </state_interface>
      <command_interface name="position"/>
    </joint>
    <gpio name="l_elbow_raw_motor_1">
      <state_interface name="speed_limit"/>
      <command_interface name="speed_limit"/>
      <state_interface name="torque_limit"/>
      <command_interface name="torque_limit"/>
      <state_interface name="p_gain"/>
      <command_interface name="p_gain"/>
      <state_interface name="i_gain"/>
      <command_interface name="i_gain"/>
      <state_interface name="d_gain"/>
      <command_interface name="d_gain"/>
    </gpio>
    <gpio name="l_elbow_raw_motor_2">
      <state_interface name="speed_limit"/>
      <command_interface name="speed_limit"/>
      <state_interface name="torque_limit"/>
      <command_interface name="torque_limit"/>
      <state_interface name="p_gain"/>
      <command_interface name="p_gain"/>
      <state_interface name="i_gain"/>
      <command_interface name="i_gain"/>
      <state_interface name="d_gain"/>
      <command_interface name="d_gain"/>
    </gpio>
    <gpio name="l_wrist">
      <state_interface name="torque">
        <param name="initial_value">0.0</param>
      </state_interface>
      <command_interface name="torque"/>
    </gpio>
    <joint name="l_wrist_roll">
      <state_interface name="position">
        <param name="initial_value">0.0</param>
      </state_interface>
      <state_interface name="velocity">
        <param name="initial_value">0.0</param>
      </state_interface>
      <state_interface name="effort">
        <param name="initial_value">0.0</param>
      </state_interface>
      <command_interface name="position"/>
    </joint>
    <joint name="l_wrist_pitch">
      <state_interface name="position">
        <param name="initial_value">0.0</param>
      </state_interface>
      <state_interface name="velocity">
        <param name="initial_value">0.0</param>
      </state_interface>
      <state_interface name="effort">
        <param name="initial_value">0.0</param>
      </state_interface>
      <command_interface name="position"/>
    </joint>
    <joint name="l_wrist_yaw">
      <state_interface name="position">
        <param name="initial_value">0.0</param>
      </state_interface>
      <state_interface name="velocity">
        <param name="initial_value">0.0</param>
      </state_interface>
      <state_interface name="effort">
        <param name="initial_value">0.0</param>
      </state_interface>
      <command_interface name="position"/>
    </joint>
    <gpio name="l_wrist_raw_motor_1">
      <state_interface name="speed_limit"/>
      <command_interface name="speed_limit"/>
      <state_interface name="torque_limit"/>
      <command_interface name="torque_limit"/>
      <state_interface name="p_gain"/>
      <command_interface name="p_gain"/>
      <state_interface name="i_gain"/>
      <command_interface name="i_gain"/>
      <state_interface name="d_gain"/>
      <command_interface name="d_gain"/>
    </gpio>
    <gpio name="l_wrist_raw_motor_2">
      <state_interface name="speed_limit"/>
      <command_interface name="speed_limit"/>
      <state_interface name="torque_limit"/>
      <command_interface name="torque_limit"/>
      <state_interface name="p_gain"/>
      <command_interface name="p_gain"/>
      <state_interface name="i_gain"/>
      <command_interface name="i_gain"/>
      <state_interface name="d_gain"/>
      <command_interface name="d_gain"/>
    </gpio>
    <gpio name="l_wrist_raw_motor_3">
      <state_interface name="speed_limit"/>
      <command_interface name="speed_limit"/>
      <state_interface name="torque_limit"/>
      <command_interface name="torque_limit"/>
      <state_interface name="p_gain"/>
      <command_interface name="p_gain"/>
      <state_interface name="i_gain"/>
      <command_interface name="i_gain"/>
      <state_interface name="d_gain"/>
      <command_interface name="d_gain"/>
    </gpio>
    <gpio name="l_hand">
      <state_interface name="torque">
        <param name="initial_value">0.0</param>
      </state_interface>
      <command_interface name="torque"/>
    </gpio>
    <joint name="l_hand_finger">
      <state_interface name="position">
        <param name="initial_value">0.0</param>
      </state_interface>
      <state_interface name="velocity">
        <param name="initial_value">0.0</param>
      </state_interface>
      <state_interface name="effort">
        <param name="initial_value">0.0</param>
      </state_interface>
      <command_interface name="position"/>
    </joint>
    <gpio name="l_hand_raw_motor_1">
      <state_interface name="speed_limit"/>
      <command_interface name="speed_limit"/>
      <state_interface name="torque_limit"/>
      <command_interface name="torque_limit"/>
      <state_interface name="p_gain"/>
      <command_interface name="p_gain"/>
      <state_interface name="i_gain"/>
      <command_interface name="i_gain"/>
      <state_interface name="d_gain"/>
      <command_interface name="d_gain"/>
    </gpio>
  </ros2_control>
  <!-- <link name="r_wrist_cam_frame"/> -->
  <!-- <joint name="r_wrist_cam_frame_joint" type="fixed"> -->
  <!--   <origin xyz="0 0 0" rpy="0.0 0 0"/> -->
  <!--   <parent link="r_gripper_palm_link"/> -->
  <!--   <child link="r_wrist_cam_frame"/> -->
  <!-- </joint> -->
  <!-- <link name="r_wrist_camera"/> -->
  <!-- <joint name="r_wrist_camera_joint" type="fixed"> -->
  <!--   <origin xyz="0.11 -0.01 0.08" rpy="0.35 -0.7 0"/> -->
  <!--   <parent link="r_wrist_cam_frame"/> -->
  <!--   <child link="r_wrist_camera"/> -->
  <!-- </joint> -->
</robot>
